Workbook

Sheet Master Data 9-9-26
A1: Uniq-ID | B1: Kolom1 | C1: Name ID | D1: Account | E1: Period | F1: Period Date | G1: Period Status | H1: Productivity Range | I1: Total % Ach. | J1: Payment Coef. | K1: Document Category | L1: Document Type | M1: Source Data | N1: Baseline/Cycle | O1: Total Doc. | P1: % Achievement | Q1: Departemen | R1: Region | S1: Productivity | T1: QEHS Inspection (ONSITE) | U1: Compliance Check (TL) | V1: Training (Class) | W1: Baseline | X1: Achievement | Y1: M4 MOS (20%) | Z1: M5 Installation (30%) | AA1: On Air (20%) | AB1: ATP Submit (20%) | AC1: ATP Approve (20%) | AD1: Total Score
A2: DC-Document_Controller-017 | B2: =Master_Data_Productivity[[#This Row],[Uniq-ID]]&"-"&Master_Data_Productivity[[#This Row],[Period]] -> DC-Document_Controller-017-M1 | C2: Lidya Juwita Apriliani wx1504642 | D2: IOH | E2: M1 | F2: 2026-03-31 - 2026-04-29 | G2: Ended | H2: Excellent | I2: 2.093 | J2: 1.05 | K2: Implementation | L2: M-08b Inbound Done | M2: ISDP | N2: 154 | O2: 108 | P2: 0.7013 | Q2: DC
A3: DC-Document_Controller-017 | B3: =Master_Data_Productivity[[#This Row],[Uniq-ID]]&"-"&Master_Data_Productivity[[#This Row],[Period]] -> DC-Document_Controller-017-M1 | C3: Lidya Juwita Apriliani wx1504642 | D3: IOH | E3: M1 | F3: 2026-03-31 - 2026-04-29 | G3: Ended | H3: Excellent | I3: 2.093 | J3: 1.05 | K3: Implementation | L3: Netgear Tagging MOS & Movement | M3: ISDP | N3: 168 | O3: 140 | P3: 0.8333 | Q3: DC
A4: DC-Document_Controller-017 | B4: =Master_Data_Productivity[[#This Row],[Uniq-ID]]&"-"&Master_Data_Productivity[[#This Row],[Period]] -> DC-Document_Controller-017-M1 | C4: Lidya Juwita Apriliani wx1504642 | D4: IOH | E4: M1 | F4: 2026-03-31 - 2026-04-29 | G4: Ended | H4: Excellent | I4: 2.093 | J4: 1.05 | K4: Acceptance | L4: ATP Endorse - Wireless | M4: ISDP | N4: 616 | O4: 344 | P4: 0.5584 | Q4: DC
A5: DC-Document_Controller-017 | B5: =Master_Data_Productivity[[#This Row],[Uniq-ID]]&"-"&Master_Data_Productivity[[#This Row],[Period]] -> DC-Document_Controller-017-M2 | C5: Lidya Juwita Apriliani wx1504642 | D5: IOH | E5: M2 | F5: 2026-04-30 - 2026-05-30 | G5: Ended | H5: Excellent | I5: 2.347 | J5: 1.17 | K5: Implementation | L5: M-08b Inbound Done | M5: ISDP | N5: 154 | O5: 115 | P5: 0.7468 | Q5: DC
A6: DC-Document_Controller-017 | B6: =Master_Data_Productivity[[#This Row],[Uniq-ID]]&"-"&Master_Data_Productivity[[#This Row],[Period]] -> DC-Document_Controller-017-M2 | C6: Lidya Juwita Apriliani wx1504642 | D6: IOH | E6: M2 | F6: 2026-04-30 - 2026-05-30 | G6: Ended | H6: Excellent | I6: 2.347 | J6: 1.17 | K6: Implementation | L6: Netgear Tagging MOS & Movement | M6: ISDP | N6: 168 | O6: 180 | P6: 1.0714 | Q6: DC
A7: DC-Document_Controller-017 | B7: =Master_Data_Productivity[[#This Row],[Uniq-ID]]&"-"&Master_Data_Productivity[[#This Row],[Period]] -> DC-Document_Controller-017-M2 | C7: Lidya Juwita Apriliani wx1504642 | D7: IOH | E7: M2 | F7: 2026-04-30 - 2026-05-30 | G7: Ended | H7: Excellent | I7: 2.347 | J7: 1.17 | K7: Acceptance | L7: ATP Endorse - Wireless | M7: ISDP | N7: 616 | O7: 326 | P7: 0.5292 | Q7: DC
A8: DC-Document_Controller-017 | B8: =Master_Data_Productivity[[#This Row],[Uniq-ID]]&"-"&Master_Data_Productivity[[#This Row],[Period]] -> DC-Document_Controller-017-M3 | C8: Lidya Juwita Apriliani wx1504642 | D8: IOH | E8: M3 | F8: 2026-05-31 - 2026-06-29 | G8: Ended | H8: Excellent | I8: 3.241 | J8: 1.5 | K8: Acceptance | L8: ATP Endorse - Wireless | M8: ISDP | N8: 616 | O8: 72 | P8: 0.1169 | Q8: DC
A9: DC-Document_Controller-017 | B9: =Master_Data_Productivity[[#This Row],[Uniq-ID]]&"-"&Master_Data_Productivity[[#This Row],[Period]] -> DC-Document_Controller-017-M3 | C9: Lidya Juwita Apriliani wx1504642 | D9: IOH | E9: M3 | F9: 2026-05-31 - 2026-06-29 | G9: Ended | H9: Excellent | I9: 3.241 | J9: 1.5 | K9: Acceptance | L9: BAUT/BAMS PAC/BAMG FAC - Wireless | M9: Datalink | O9: 239 | Q9: DC
A10: DC-Document_Controller-017 | B10: =Master_Data_Productivity[[#This Row],[Uniq-ID]]&"-"&Master_Data_Productivity[[#This Row],[Period]] -> DC-Document_Controller-017-M3 | C10: Lidya Juwita Apriliani wx1504642 | D10: IOH | E10: M3 | F10: 2026-05-31 - 2026-06-29 | G10: Ended | H10: Excellent | I10: 3.241 | J10: 1.5 | K10: Acceptance | L10: Change Request (CR) | M10: Datalink | N10: 308 | O10: 6 | P10: 0.0195 | Q10: DC
A11: DC-Document_Controller-017 | B11: =Master_Data_Productivity[[#This Row],[Uniq-ID]]&"-"&Master_Data_Productivity[[#This Row],[Period]] -> DC-Document_Controller-017-M3 | C11: Lidya Juwita Apriliani wx1504642 | D11: IOH | E11: M3 | F11: 2026-05-31 - 2026-06-29 | G11: Ended | H11: Excellent | I11: 3.241 | J11: 1.5 | K11: Implementation | L11: M-08b Inbound Done | M11: ISDP | N11: 154 | O11: 151 | P11: 0.9805 | Q11: DC
A12: DC-Document_Controller-017 | B12: =Master_Data_Productivity[[#This Row],[Uniq-ID]]&"-"&Master_Data_Productivity[[#This Row],[Period]] -> DC-Document_Controller-017-M3 | C12: Lidya Juwita Apriliani wx1504642 | D12: IOH | E12: M3 | F12: 2026-05-31 - 2026-06-29 | G12: Ended | H12: Excellent | I12: 3.241 | J12: 1.5 | K12: Implementation | L12: Netgear Tagging MOS & Movement | M12: ISDP | N12: 168 | O12: 340 | P12: 2.0238 | Q12: DC
A13: DC-Document_Controller-017 | B13: =Master_Data_Productivity[[#This Row],[Uniq-ID]]&"-"&Master_Data_Productivity[[#This Row],[Period]] -> DC-Document_Controller-017-M3 | C13: Lidya Juwita Apriliani wx1504642 | D13: IOH | E13: M3 | F13: 2026-05-31 - 2026-06-29 | G13: Ended | H13: Excellent | I13: 3.241 | J13: 1.5 | K13: Pre-implementation | L13: Change Request (CR) | M13: Datalink | N13: 308 | O13: 31 | P13: 0.1006 | Q13: DC
A14: DC-Document_Controller-017 | B14: =Master_Data_Productivity[[#This Row],[Uniq-ID]]&"-"&Master_Data_Productivity[[#This Row],[Period]] -> DC-Document_Controller-017-M4 | C14: Lidya Juwita Apriliani wx1504642 | D14: IOH | E14: M4 | F14: 2026-06-30 - 2026-07-30 | G14: Ended | H14: Excellent | I14: 3.907 | J14: 1.5 | L14: BAUT/BAMS PAC/BAMG FAC - Wireless | M14: ISDP | O14: 695 | Q14: DC
A15: DC-Document_Controller-017 | B15: =Master_Data_Productivity[[#This Row],[Uniq-ID]]&"-"&Master_Data_Productivity[[#This Row],[Period]] -> DC-Document_Controller-017-M4 | C15: Lidya Juwita Apriliani wx1504642 | D15: IOH | E15: M4 | F15: 2026-06-30 - 2026-07-30 | G15: Ended | H15: Excellent | I15: 3.907 | J15: 1.5 | K15: Pre-implementation | L15: Change Request (CR) | M15: Datalink | N15: 308 | O15: 36 | P15: 0.1169 | Q15: DC
A16: DC-Document_Controller-017 | B16: =Master_Data_Productivity[[#This Row],[Uniq-ID]]&"-"&Master_Data_Productivity[[#This Row],[Period]] -> DC-Document_Controller-017-M4 | C16: Lidya Juwita Apriliani wx1504642 | D16: IOH | E16: M4 | F16: 2026-06-30 - 2026-07-30 | G16: Ended | H16: Excellent | I16: 3.907 | J16: 1.5 | K16: Implementation | L16: Netgear Tagging MOS & Movement | M16: ISDP | N16: 168 | O16: 154 | P16: 0.9167 | Q16: DC
A17: DC-Document_Controller-017 | B17: =Master_Data_Productivity[[#This Row],[Uniq-ID]]&"-"&Master_Data_Productivity[[#This Row],[Period]] -> DC-Document_Controller-017-M4 | C17: Lidya Juwita Apriliani wx1504642 | D17: IOH | E17: M4 | F17: 2026-06-30 - 2026-07-30 | G17: Ended | H17: Excellent | I17: 3.907 | J17: 1.5 | K17: Implementation | L17: M-08b Inbound Done | M17: ISDP | N17: 154 | O17: 189 | P17: 1.2273 | Q17: DC
A18: DC-Document_Controller-017 | B18: =Master_Data_Productivity[[#This Row],[Uniq-ID]]&"-"&Master_Data_Productivity[[#This Row],[Period]] -> DC-Document_Controller-017-M4 | C18: Lidya Juwita Apriliani wx1504642 | D18: IOH | E18: M4 | F18: 2026-06-30 - 2026-07-30 | G18: Ended | H18: Excellent | I18: 3.907 | J18: 1.5 | K18: Acceptance | L18: BAUT/BAMS PAC/BAMG FAC - Wireless | M18: ISDP | N18: 462 | O18: 544 | P18: 1.1775 | Q18: DC
A19: DC-Document_Controller-017 | B19: =Master_Data_Productivity[[#This Row],[Uniq-ID]]&"-"&Master_Data_Productivity[[#This Row],[Period]] -> DC-Document_Controller-017-M4 | C19: Lidya Juwita Apriliani wx1504642 | D19: IOH | E19: M4 | F19: 2026-06-30 - 2026-07-30 | G19: Ended | H19: Excellent | I19: 3.907 | J19: 1.5 | K19: Acceptance | L19: ATP Endorse - Wireless | M19: ISDP | N19: 616 | O19: 289 | P19: 0.4692 | Q19: DC
A20: DC-Document_Controller-017 | B20: =Master_Data_Productivity[[#This Row],[Uniq-ID]]&"-"&Master_Data_Productivity[[#This Row],[Period]] -> DC-Document_Controller-017-M5 | C20: Lidya Juwita Apriliani wx1504642 | D20: IOH | E20: M5 | F20: 2026-07-31 - 2026-08-30 | G20: Ended | H20: Normal | I20: 1.683 | J20: 1 | K20: Acceptance | L20: ATP Endorse - Wireless | M20: ISDP | N20: 616 | O20: 50 | P20: 0.0812 | Q20: DC
A21: DC-Document_Controller-017 | B21: =Master_Data_Productivity[[#This Row],[Uniq-ID]]&"-"&Master_Data_Productivity[[#This Row],[Period]] -> DC-Document_Controller-017-M5 | C21: Lidya Juwita Apriliani wx1504642 | D21: IOH | E21: M5 | F21: 2026-07-31 - 2026-08-30 | G21: Ended | H21: Normal | I21: 1.683 | J21: 1 | K21: Acceptance | L21: BAUT/BAMS PAC/BAMG FAC - Wireless | M21: ISDP | N21: 462 | O21: 533 | P21: 1.1537 | Q21: DC
A22: DC-Document_Controller-017 | B22: =Master_Data_Productivity[[#This Row],[Uniq-ID]]&"-"&Master_Data_Productivity[[#This Row],[Period]] -> DC-Document_Controller-017-M5 | C22: Lidya Juwita Apriliani wx1504642 | D22: IOH | E22: M5 | F22: 2026-07-31 - 2026-08-30 | G22: Ended | H22: Normal | I22: 1.683 | J22: 1 | K22: Implementation | L22: M-08b Inbound Done | M22: ISDP | N22: 154 | O22: 52 | P22: 0.3377 | Q22: DC
A23: DC-Document_Controller-017 | B23: =Master_Data_Productivity[[#This Row],[Uniq-ID]]&"-"&Master_Data_Productivity[[#This Row],[Period]] -> DC-Document_Controller-017-M5 | C23: Lidya Juwita Apriliani wx1504642 | D23: IOH | E23: M5 | F23: 2026-07-31 - 2026-08-30 | G23: Ended | H23: Normal | I23: 1.683 | J23: 1 | K23: Pre-implementation | L23: Change Request (CR) | M23: Datalink | N23: 308 | O23: 34 | P23: 0.1104 | Q23: DC
A24: DC-Document_Controller-017 | B24: =Master_Data_Productivity[[#This Row],[Uniq-ID]]&"-"&Master_Data_Productivity[[#This Row],[Period]] -> DC-Document_Controller-017-M5 | C24: Lidya Juwita Apriliani wx1504642 | D24: IOH | E24: M5 | F24: 2026-07-31 - 2026-08-30 | G24: Ended | H24: Normal | I24: 1.683 | J24: 1 | L24: BAUT/BAMS PAC/BAMG FAC - Wireless | M24: ISDP | O24: 421 | Q24: DC
A25: DC-Document_Controller-017 | B25: =Master_Data_Productivity[[#This Row],[Uniq-ID]]&"-"&Master_Data_Productivity[[#This Row],[Period]] -> DC-Document_Controller-017-M6 | C25: Lidya Juwita Apriliani wx1504642 | D25: IOH | E25: M6 | F25: 2026-08-31 - 2026-09-29 | G25: Ongoing | H25: Poor | I25: 0.013 | J25: 0.5 | K25: Implementation | L25: M-08b Inbound Done | M25: ISDP | N25: 154 | O25: 2 | P25: 0.013 | Q25: DC
A26: DC-Document_Controller-023 | B26: =Master_Data_Productivity[[#This Row],[Uniq-ID]]&"-"&Master_Data_Productivity[[#This Row],[Period]] -> DC-Document_Controller-023-M1 | C26: Ika Setianingsih wx1507364 | D26: XLSMART | E26: M1 | F26: 2026-04-01 - 2026-04-30 | G26: Ended | H26: Excellent | I26: 24.5 | J26: 1.5 | K26: Acceptance | L26: IPS Submit | M26: Datalink | N26: 4 | O26: 98 | P26: 24.5 | Q26: DC
A27: DC-Document_Controller-023 | B27: =Master_Data_Productivity[[#This Row],[Uniq-ID]]&"-"&Master_Data_Productivity[[#This Row],[Period]] -> DC-Document_Controller-023-M2 | C27: Ika Setianingsih wx1507364 | D27: XLSMART | E27: M2 | F27: 2026-05-01 - 2026-05-31 | G27: Ended | H27: Excellent | I27: 5.032 | J27: 1.5 | K27: PO Mapping Initial | L27: PO Mapping | M27: Datalink | N27: 31 | O27: 156 | P27: 5.0323 | Q27: DC
A28: DC-Document_Controller-023 | B28: =Master_Data_Productivity[[#This Row],[Uniq-ID]]&"-"&Master_Data_Productivity[[#This Row],[Period]] -> DC-Document_Controller-023-M3 | C28: Ika Setianingsih wx1507364 | D28: XLSMART | E28: M3 | F28: 2026-06-01 - 2026-06-30 | G28: Ended | H28: Normal | I28: 1.516 | J28: 1 | K28: PO Mapping Initial | L28: PO Mapping | M28: Datalink | O28: 47 | Q28: DC
A29: DC-Document_Controller-023 | B29: =Master_Data_Productivity[[#This Row],[Uniq-ID]]&"-"&Master_Data_Productivity[[#This Row],[Period]] -> DC-Document_Controller-023-M3 | C29: Ika Setianingsih wx1507364 | D29: XLSMART | E29: M3 | F29: 2026-06-01 - 2026-06-30 | G29: Ended | H29: Normal | I29: 1.516 | J29: 1 | K29: PO Mapping Initial | L29: PO Mapping | M29: Datalink | N29: 31 | O29: 47 | P29: 1.5161 | Q29: DC
A30: DC-Document_Controller-023 | B30: =Master_Data_Productivity[[#This Row],[Uniq-ID]]&"-"&Master_Data_Productivity[[#This Row],[Period]] -> DC-Document_Controller-023-M3 | C30: Ika Setianingsih wx1507364 | D30: XLSMART | E30: M3 | F30: 2026-06-01 - 2026-06-30 | G30: Ended | H30: Normal | I30: 1.516 | J30: 1 | K30: Acceptance | L30: PO Mapping | M30: Datalink | O30: 38 | Q30: DC
A31: DC-Document_Controller-023 | B31: =Master_Data_Productivity[[#This Row],[Uniq-ID]]&"-"&Master_Data_Productivity[[#This Row],[Period]] -> DC-Document_Controller-023-M4 | C31: Ika Setianingsih wx1507364 | D31: XLSMART | E31: M4 | F31: 2026-07-01 - 2026-07-31 | G31: Ended | H31: Excellent | I31: 43.25 | J31: 1.5 | K31: Acceptance | L31: IPS Submit | M31: Datalink | N31: 4 | O31: 173 | P31: 43.25 | Q31: DC
A32: DC-Document_Controller-023 | B32: =Master_Data_Productivity[[#This Row],[Uniq-ID]]&"-"&Master_Data_Productivity[[#This Row],[Period]] -> DC-Document_Controller-023-M5 | C32: Ika Setianingsih wx1507364 | D32: XLSMART | E32: M5 | F32: 2026-08-01 - 2026-08-31 | G32: Ended | H32: Excellent | I32: 3.097 | J32: 1.5 | K32: Pre-implementation | L32: PO Mapping | M32: Datalink | N32: 31 | O32: 96 | P32: 3.0968 | Q32: DC
A33: DC-Document_Controller-023 | B33: =Master_Data_Productivity[[#This Row],[Uniq-ID]]&"-"&Master_Data_Productivity[[#This Row],[Period]] -> DC-Document_Controller-023-M6 | C33: Ika Setianingsih wx1507364 | D33: XLSMART | E33: M6 | F33: 2026-09-01 - 2026-09-30 | G33: Ongoing | H33: Poor | I33: 0 | Q33: DC
A34: DC-Document_Controller-022 | B34: =Master_Data_Productivity[[#This Row],[Uniq-ID]]&"-"&Master_Data_Productivity[[#This Row],[Period]] -> DC-Document_Controller-022-M1 | C34: Alifya Rahma Asy Syaffa wx1504637 | D34: Surge | E34: M1 | F34: 2026-04-01 - 2026-04-30 | G34: Ended | H34: Excellent | I34: 2.018 | J34: 1.01 | K34: Pre-implementation | L34: Site Permit | M34: Datalink | N34: 308 | O34: 22 | P34: 0.0714 | Q34: DC
A35: DC-Document_Controller-022 | B35: =Master_Data_Productivity[[#This Row],[Uniq-ID]]&"-"&Master_Data_Productivity[[#This Row],[Period]] -> DC-Document_Controller-022-M1 | C35: Alifya Rahma Asy Syaffa wx1504637 | D35: Surge | E35: M1 | F35: 2026-04-01 - 2026-04-30 | G35: Ended | H35: Excellent | I35: 2.018 | J35: 1.01 | K35: Pre-implementation | L35: Site Permit | M35: Datalink | N35: 26 | O35: 22 | P35: 0.8462 | Q35: DC
A36: DC-Document_Controller-022 | B36: =Master_Data_Productivity[[#This Row],[Uniq-ID]]&"-"&Master_Data_Productivity[[#This Row],[Period]] -> DC-Document_Controller-022-M1 | C36: Alifya Rahma Asy Syaffa wx1504637 | D36: Surge | E36: M1 | F36: 2026-04-01 - 2026-04-30 | G36: Ended | H36: Excellent | I36: 2.018 | J36: 1.01 | K36: Pre-implementation | L36: Site Permit | M36: Datalink | N36: 20 | O36: 22 | P36: 1.1 | Q36: DC
A37: DC-Document_Controller-022 | B37: =Master_Data_Productivity[[#This Row],[Uniq-ID]]&"-"&Master_Data_Productivity[[#This Row],[Period]] -> DC-Document_Controller-022-M2 | C37: Alifya Rahma Asy Syaffa wx1504637 | D37: Surge | E37: M2 | F37: 2026-05-01 - 2026-05-31 | G37: Ended | H37: Normal | I37: 1.926 | J37: 1 | K37: Pre-implementation | L37: Site Permit | M37: Datalink | N37: 20 | O37: 21 | P37: 1.05 | Q37: DC
A38: DC-Document_Controller-022 | B38: =Master_Data_Productivity[[#This Row],[Uniq-ID]]&"-"&Master_Data_Productivity[[#This Row],[Period]] -> DC-Document_Controller-022-M2 | C38: Alifya Rahma Asy Syaffa wx1504637 | D38: Surge | E38: M2 | F38: 2026-05-01 - 2026-05-31 | G38: Ended | H38: Normal | I38: 1.926 | J38: 1 | K38: Pre-implementation | L38: Site Permit | M38: Datalink | N38: 26 | O38: 21 | P38: 0.8077 | Q38: DC
A39: DC-Document_Controller-022 | B39: =Master_Data_Productivity[[#This Row],[Uniq-ID]]&"-"&Master_Data_Productivity[[#This Row],[Period]] -> DC-Document_Controller-022-M2 | C39: Alifya Rahma Asy Syaffa wx1504637 | D39: Surge | E39: M2 | F39: 2026-05-01 - 2026-05-31 | G39: Ended | H39: Normal | I39: 1.926 | J39: 1 | K39: Pre-implementation | L39: Site Permit | M39: Datalink | N39: 308 | O39: 21 | P39: 0.0682 | Q39: DC
A40: DC-Document_Controller-022 | B40: =Master_Data_Productivity[[#This Row],[Uniq-ID]]&"-"&Master_Data_Productivity[[#This Row],[Period]] -> DC-Document_Controller-022-M3 | C40: Alifya Rahma Asy Syaffa wx1504637 | D40: Surge | E40: M3 | F40: 2026-06-01 - 2026-06-30 | G40: Ended | H40: Poor | I40: 0.825 | J40: 0.83 | K40: Pre-implementation | L40: Site Permit | M40: Datalink | N40: 26 | O40: 9 | P40: 0.3462 | Q40: DC
...

Sheet Master Data 14-9-2026
A1: Role | B1: Uniq-ID | C1: Column1 | D1: Name ID | E1: Account | F1: Region | G1: Period | H1: Period Date | I1: Period Status | J1: Productivity Range | K1: Productivity | L1: Payment Coef. | M1: Total % Ach. | N1: Document Category | O1: Document Type | P1: Source Data | Q1: Baseline/Cycle | R1: Total Doc. | S1: % Achievement | T1: QEHS Inspection (ONSITE) | U1: Compliance Check (TL) | V1: Training (Class) | W1: Baseline | X1: Achievement | Y1: Onsite Clock-In | Z1: M-06 Integrated | AA1: M-04 MOS (20%) | AB1: M-05 Installation (30%) | AC1: On Air (20%) | AD1: ATP Submit (20%) | AE1: ATP Approve (20%) | AF1: Total Score
A2: DC | B2: DC-Document_Controller-001 | C2: =Data_Master[[#This Row],[Uniq-ID]]&"-"&Data_Master[[#This Row],[Period]] -> DC-Document_Controller-001-M1 | D2: Sri Hardianti Purnamasari wx1503627 | E2: TELKOMSEL | G2: M1 | H2: 2026-03-23 - 2026-04-22 | I2: Ended | J2: Excellent | L2: 1.05 | M2: 2.109 | N2: Implementation | O2: Tagging Dismantle Material | P2: ISDP | Q2: 35 | R2: 28 | S2: 0.8
A3: DC | B3: DC-Document_Controller-001 | C3: =Data_Master[[#This Row],[Uniq-ID]]&"-"&Data_Master[[#This Row],[Period]] -> DC-Document_Controller-001-M1 | D3: Sri Hardianti Purnamasari wx1503627 | E3: TELKOMSEL | G3: M1 | H3: 2026-03-23 - 2026-04-22 | I3: Ended | J3: Excellent | L3: 1.05 | M3: 2.109 | N3: Implementation | O3: Tagging Installation | P3: ISDP | Q3: 32 | R3: 41 | S3: 1.2813
A4: DC | B4: DC-Document_Controller-001 | C4: =Data_Master[[#This Row],[Uniq-ID]]&"-"&Data_Master[[#This Row],[Period]] -> DC-Document_Controller-001-M1 | D4: Sri Hardianti Purnamasari wx1503627 | E4: TELKOMSEL | G4: M1 | H4: 2026-03-23 - 2026-04-22 | I4: Ended | J4: Excellent | L4: 1.05 | M4: 2.109 | N4: Implementation | O4: M-08 Dismantle | P4: ISDP | Q4: 36 | R4: 1 | S4: 0.0278
A5: DC | B5: DC-Document_Controller-001 | C5: =Data_Master[[#This Row],[Uniq-ID]]&"-"&Data_Master[[#This Row],[Period]] -> DC-Document_Controller-001-M2 | D5: Sri Hardianti Purnamasari wx1503627 | E5: TELKOMSEL | G5: M2 | H5: 2026-04-23 - 2026-05-22 | I5: Ended | J5: Excellent | L5: 1.09 | M5: 2.179 | N5: Implementation | O5: M-08 Dismantle | P5: ISDP | Q5: 36 | R5: 12 | S5: 0.3333
A6: DC | B6: DC-Document_Controller-001 | C6: =Data_Master[[#This Row],[Uniq-ID]]&"-"&Data_Master[[#This Row],[Period]] -> DC-Document_Controller-001-M2 | D6: Sri Hardianti Purnamasari wx1503627 | E6: TELKOMSEL | G6: M2 | H6: 2026-04-23 - 2026-05-22 | I6: Ended | J6: Excellent | L6: 1.09 | M6: 2.179 | N6: Implementation | O6: Tagging Dismantle Material | P6: ISDP | Q6: 35 | R6: 18 | S6: 0.5143
A7: DC | B7: DC-Document_Controller-001 | C7: =Data_Master[[#This Row],[Uniq-ID]]&"-"&Data_Master[[#This Row],[Period]] -> DC-Document_Controller-001-M2 | D7: Sri Hardianti Purnamasari wx1503627 | E7: TELKOMSEL | G7: M2 | H7: 2026-04-23 - 2026-05-22 | I7: Ended | J7: Excellent | L7: 1.09 | M7: 2.179 | N7: Implementation | O7: Tagging Installation | P7: ISDP | Q7: 32 | R7: 18 | S7: 0.5625
A8: DC | B8: DC-Document_Controller-001 | C8: =Data_Master[[#This Row],[Uniq-ID]]&"-"&Data_Master[[#This Row],[Period]] -> DC-Document_Controller-001-M2 | D8: Sri Hardianti Purnamasari wx1503627 | E8: TELKOMSEL | G8: M2 | H8: 2026-04-23 - 2026-05-22 | I8: Ended | J8: Excellent | L8: 1.09 | M8: 2.179 | N8: Pre-implementation | O8: CAF Application | P8: ISDP | Q8: 26 | R8: 20 | S8: 0.7692
A9: DC | B9: DC-Document_Controller-001 | C9: =Data_Master[[#This Row],[Uniq-ID]]&"-"&Data_Master[[#This Row],[Period]] -> DC-Document_Controller-001-M3 | D9: Sri Hardianti Purnamasari wx1503627 | E9: TELKOMSEL | G9: M3 | H9: 2026-05-23 - 2026-06-22 | I9: Ended | J9: Normal | L9: 1 | M9: 1.888 | N9: Implementation | O9: Tagging Installation | P9: ISDP | Q9: 32 | R9: 44 | S9: 1.375
A10: DC | B10: DC-Document_Controller-001 | C10: =Data_Master[[#This Row],[Uniq-ID]]&"-"&Data_Master[[#This Row],[Period]] -> DC-Document_Controller-001-M3 | D10: Sri Hardianti Purnamasari wx1503627 | E10: TELKOMSEL | G10: M3 | H10: 2026-05-23 - 2026-06-22 | I10: Ended | J10: Normal | L10: 1 | M10: 1.888 | N10: Implementation | O10: Tagging Dismantle Material | P10: ISDP | Q10: 35 | R10: 16 | S10: 0.4571
A11: DC | B11: DC-Document_Controller-001 | C11: =Data_Master[[#This Row],[Uniq-ID]]&"-"&Data_Master[[#This Row],[Period]] -> DC-Document_Controller-001-M3 | D11: Sri Hardianti Purnamasari wx1503627 | E11: TELKOMSEL | G11: M3 | H11: 2026-05-23 - 2026-06-22 | I11: Ended | J11: Normal | L11: 1 | M11: 1.888 | N11: Implementation | O11: M-08 Dismantle | P11: ISDP | Q11: 36 | R11: 2 | S11: 0.0556
A12: DC | B12: DC-Document_Controller-001 | C12: =Data_Master[[#This Row],[Uniq-ID]]&"-"&Data_Master[[#This Row],[Period]] -> DC-Document_Controller-001-M4 | D12: Sri Hardianti Purnamasari wx1503627 | E12: TELKOMSEL | G12: M4 | H12: 2026-06-23 - 2026-07-22 | I12: Ended | J12: Excellent | L12: 1.5 | M12: 3.856 | N12: Implementation | O12: Tagging Installation | P12: ISDP | Q12: 32 | R12: 32 | S12: 1
A13: DC | B13: DC-Document_Controller-001 | C13: =Data_Master[[#This Row],[Uniq-ID]]&"-"&Data_Master[[#This Row],[Period]] -> DC-Document_Controller-001-M4 | D13: Sri Hardianti Purnamasari wx1503627 | E13: TELKOMSEL | G13: M4 | H13: 2026-06-23 - 2026-07-22 | I13: Ended | J13: Excellent | L13: 1.5 | M13: 3.856 | N13: Implementation | O13: M-08 Dismantle | P13: ISDP | Q13: 36 | R13: 38 | S13: 1.0556
... A19: DC | B19: DC-Document_Controller-001 | C19: =Data_Master[[#This Row],[Uniq-ID]]&"-"&Data_Master[[#This Row],[Period]] -> DC-Document_Controller-001-M6 | D19: Sri Hardianti Purnamasari wx1503627 | E19: TELKOMSEL | G19: M6 | H19: 2026-08-23 - 2026-09-22 | I19: Ongoing | J19: Poor | L19: 0.53 | M19: 0.535 | N19: Implementation | O19: Tagging Dismantle Material | P19: ISDP | Q19: 35 | R19: 9 | S19: 0.2571
A20: DC | B20: DC-Document_Controller-002 | C20: =Data_Master[[#This Row],[Uniq-ID]]&"-"&Data_Master[[#This Row],[Period]] -> DC-Document_Controller-002-M1 | D20: Rifan Azkia wx1504665 | E20: XLSMART | G20: M1 | H20: 2026-03-23 - 2026-04-22 | I20: Ended | J20: Poor | M20: 0
A21: DC | B21: DC-Document_Controller-002 | C21: =Data_Master[[#This Row],[Uniq-ID]]&"-"&Data_Master[[#This Row],[Period]] -> DC-Document_Controller-002-M2 | D21: Rifan Azkia wx1504665 | E21: XLSMART | G21: M2 | H21: 2026-04-23 - 2026-05-22 | I21: Ended | J21: Poor | M21: 0
A22: DC | B22: DC-Document_Controller-002 | C22: =Data_Master[[#This Row],[Uniq-ID]]&"-"&Data_Master[[#This Row],[Period]] -> DC-Document_Controller-002-M3 | D22: Rifan Azkia wx1504665 | E22: XLSMART | G22: M3 | H22: 2026-05-23 - 2026-06-22 | I22: Ended | J22: Poor | M22: 0
A23: DC | B23: DC-Document_Controller-002 | C23: =Data_Master[[#This Row],[Uniq-ID]]&"-"&Data_Master[[#This Row],[Period]] -> DC-Document_Controller-002-M4 | D23: Rifan Azkia wx1504665 | E23: XLSMART | G23: M4 | H23: 2026-06-23 - 2026-07-22 | I23: Ended | J23: Poor | L23: 0.5 | M23: 0.015 | N23: Implementation | O23: PLN Upgrade | P23: ISDP | Q23: 66 | R23: 1 | S23: 0.0152
A24: DC | B24: DC-Document_Controller-002 | C24: =Data_Master[[#This Row],[Uniq-ID]]&"-"&Data_Master[[#This Row],[Period]] -> DC-Document_Controller-002-M5 | D24: Rifan Azkia wx1504665 | E24: XLSMART | G24: M5 | H24: 2026-07-23 - 2026-08-22 | I24: Ended | J24: Poor | M24: 0
A25: DC | B25: DC-Document_Controller-002 | C25: =Data_Master[[#This Row],[Uniq-ID]]&"-"&Data_Master[[#This Row],[Period]] -> DC-Document_Controller-002-M6 | D25: Rifan Azkia wx1504665 | E25: XLSMART | G25: M6 | H25: 2026-08-23 - 2026-09-22 | I25: Ongoing | J25: Poor | L25: 0.5 | M25: 0.005 | N25: Implementation | O25: Dismantle Inbound | P25: ISDP | Q25: 220 | R25: 1 | S25: 0.0045
A26: DC | B26: DC-Document_Controller-003 | C26: =Data_Master[[#This Row],[Uniq-ID]]&"-"&Data_Master[[#This Row],[Period]] -> DC-Document_Controller-003-M1 | D26: Gigih Dharma Sulistya wx1503511 | E26: TELKOMSEL | G26: M1 | H26: 2026-03-23 - 2026-04-22 | I26: Ended | J26: Normal | L26: 1 | M26: 1.744 | N26: Implementation | O26: M-08 Dismantle | P26: ISDP | Q26: 36 | R26: 35 | S26: 0.9722
A27: DC | B27: DC-Document_Controller-003 | C27: =Data_Master[[#This Row],[Uniq-ID]]&"-"&Data_Master[[#This Row],[Period]] -> DC-Document_Controller-003-M1 | D27: Gigih Dharma Sulistya wx1503511 | E27: TELKOMSEL | G27: M1 | H27: 2026-03-23 - 2026-04-22 | I27: Ended | J27: Normal | L27: 1 | M27: 1.744 | N27: Implementation | O27: Tagging Dismantle Material | P27: ISDP | Q27: 35 | R27: 27 | S27: 0.7714
A28: DC | B28: DC-Document_Controller-003 | C28: =Data_Master[[#This Row],[Uniq-ID]]&"-"&Data_Master[[#This Row],[Period]] -> DC-Document_Controller-003-M2 | D28: Gigih Dharma Sulistya wx1503511 | E28: TELKOMSEL | G28: M2 | H28: 2026-04-23 - 2026-05-22 | I28: Ended | J28: Normal | L28: 1 | M28: 1.864 | N28: Implementation | O28: M-08 Dismantle | P28: ISDP | Q28: 36 | R28: 27 | S28: 0.75
A29: DC | B29: DC-Document_Controller-003 | C29: =Data_Master[[#This Row],[Uniq-ID]]&"-"&Data_Master[[#This Row],[Period]] -> DC-Document_Controller-003-M2 | D29: Gigih Dharma Sulistya wx1503511 | E29: TELKOMSEL | G29: M2 | H29: 2026-04-23 - 2026-05-22 | I29: Ended | J29: Normal | L29: 1 | M29: 1.864 | N29: Implementation | O29: Tagging Dismantle Material | P29: ISDP | Q29: 35 | R29: 39 | S29: 1.1143
A30: DC | B30: DC-Document_Controller-003 | C30: =Data_Master[[#This Row],[Uniq-ID]]&"-"&Data_Master[[#This Row],[Period]] -> DC-Document_Controller-003-M3 | D30: Gigih Dharma Sulistya wx1503511 | E30: TELKOMSEL | G30: M3 | H30: 2026-05-23 - 2026-06-22 | I30: Ended | J30: Excellent | L30: 1.5 | M30: 4.173 | N30: Implementation | O30: M-08 Dismantle | P30: ISDP | Q30: 36 | R30: 71 | S30: 1.9722
A31: DC | B31: DC-Document_Controller-003 | C31: =Data_Master[[#This Row],[Uniq-ID]]&"-"&Data_Master[[#This Row],[Period]] -> DC-Document_Controller-003-M3 | D31: Gigih Dharma Sulistya wx1503511 | E31: TELKOMSEL | G31: M3 | H31: 2026-05-23 - 2026-06-22 | I31: Ended | J31: Excellent | L31: 1.5 | M31: 4.173 | N31: Implementation | O31: Tagging Dismantle Material | P31: ISDP | Q31: 35 | R31: 73 | S31: 2.0857
A32: DC | B32: DC-Document_Controller-003 | C32: =Data_Master[[#This Row],[Uniq-ID]]&"-"&Data_Master[[#This Row],[Period]] -> DC-Document_Controller-003-M3 | D32: Gigih Dharma Sulistya wx1503511 | E32: TELKOMSEL | G32: M3 | H32: 2026-05-23 - 2026-06-22 | I32: Ended | J32: Excellent | L32: 1.5 | M32: 4.173 | N32: Pre-implementation | O32: CAF Application | P32: ISDP | Q32: 26 | R32: 3 | S32: 0.1154
A33: DC | B33: DC-Document_Controller-003 | C33: =Data_Master[[#This Row],[Uniq-ID]]&"-"&Data_Master[[#This Row],[Period]] -> DC-Document_Controller-003-M4 | D33: Gigih Dharma Sulistya wx1503511 | E33: TELKOMSEL | G33: M4 | H33: 2026-06-23 - 2026-07-22 | I33: Ended | J33: Excellent | L33: 1.5 | M33: 4.171 | N33: Implementation | O33: M-08 Dismantle | P33: ISDP | Q33: 36 | R33: 48 | S33: 1.3333
A34: DC | B34: DC-Document_Controller-003 | C34: =Data_Master[[#This Row],[Uniq-ID]]&"-"&Data_Master[[#This Row],[Period]] -> DC-Document_Controller-003-M4 | D34: Gigih Dharma Sulistya wx1503511 | E34: TELKOMSEL | G34: M4 | H34: 2026-06-23 - 2026-07-22 | I34: Ended | J34: Excellent | L34: 1.5 | M34: 4.171 | N34: Implementation | O34: Tagging Dismantle Material | P34: ISDP | Q34: 35 | R34: 32 | S34: 0.9143
A35: DC | B35: DC-Document_Controller-003 | C35: =Data_Master[[#This Row],[Uniq-ID]]&"-"&Data_Master[[#This Row],[Period]] -> DC-Document_Controller-003-M4 | D35: Gigih Dharma Sulistya wx1503511 | E35: TELKOMSEL | G35: M4 | H35: 2026-06-23 - 2026-07-22 | I35: Ended | J35: Excellent | L35: 1.5 | M35: 4.171 | N35: Pre-implementation | O35: CAF Application | P35: ISDP | Q35: 26 | R35: 50 | S35: 1.9231
A36: DC | B36: DC-Document_Controller-003 | C36: =Data_Master[[#This Row],[Uniq-ID]]&"-"&Data_Master[[#This Row],[Period]] -> DC-Document_Controller-003-M5 | D36: Gigih Dharma Sulistya wx1503511 | E36: TELKOMSEL | G36: M5 | H36: 2026-07-23 - 2026-08-22 | I36: Ended | J36: Excellent | L36: 1.5 | M36: 3.606 | N36: Implementation | O36: Tagging Dismantle Material | P36: ISDP | Q36: 35 | R36: 64 | S36: 1.8286
... A54: DC | B54: DC-Document_Controller-004 | C54: =Data_Master[[#This Row],[Uniq-ID]]&"-"&Data_Master[[#This Row],[Period]] -> DC-Document_Controller-004-M5 | D54: Hyang Iman Kinasih Gusti wx1503650 | E54: IOH | G54: M5 | H54: 2026-07-23 - 2026-08-22 | I54: Ended | J54: Excellent | L54: 1.5 | M54: 9.171 | N54: Pre-implementation | O54: Site Permit | P54: Datalink | Q54: 20 | R54: 100 | S54: 5
A55: DC | B55: DC-Document_Controller-004 | C55: =Data_Master[[#This Row],[Uniq-ID]]&"-"&Data_Master[[#This Row],[Period]] -> DC-Document_Controller-004-M6 | D55: Hyang Iman Kinasih Gusti wx1503650 | E55: IOH | G55: M6 | H55: 2026-08-23 - 2026-09-22 | I55: Ongoing | J55: Poor | M55: 0
A56: DC | B56: DC-Document_Controller-005 | C56: =Data_Master[[#This Row],[Uniq-ID]]&"-"&Data_Master[[#This Row],[Period]] -> DC-Document_Controller-005-M1 | D56: F Albert Jacob wx1504717 | E56: TELKOMSEL | G56: M1 | H56: 2026-03-23 - 2026-04-22 | I56: Ended | J56: Normal | L56: 1 | M56: 1.525 | N56: Implementation | O56: M-08 Dismantle | P56: ISDP | Q56: 36 | R56: 2 | S56: 0.0556
A57: DC | B57: DC-Document_Controller-005 | C57: =Data_Master[[#This Row],[Uniq-ID]]&"-"&Data_Master[[#This Row],[Period]] -> DC-Document_Controller-005-M1 | D57: F Albert Jacob wx1504717 | E57: TELKOMSEL | G57: M1 | H57: 2026-03-23 - 2026-04-22 | I57: Ended | J57: Normal | L57: 1 | M57: 1.525 | N57: Implementation | O57: Tagging Dismantle Material | P57: ISDP | Q57: 35 | R57: 7 | S57: 0.2
A58: DC | B58: DC-Document_Controller-005 | C58: =Data_Master[[#This Row],[Uniq-ID]]&"-"&Data_Master[[#This Row],[Period]] -> DC-Document_Controller-005-M1 | D58: F Albert Jacob wx1504717 | E58: TELKOMSEL | G58: M1 | H58: 2026-03-23 - 2026-04-22 | I58: Ended | J58: Normal | L58: 1 | M58: 1.525 | N58: Pre-implementation | O58: CAF Application | P58: ISDP | Q58: 26 | R58: 33 | S58: 1.2692
A59: DC | B59: DC-Document_Controller-005 | C59: =Data_Master[[#This Row],[Uniq-ID]]&"-"&Data_Master[[#This Row],[Period]] -> DC-Document_Controller-005-M2 | D59: F Albert Jacob wx1504717 | E59: TELKOMSEL | G59: M2 | H59: 2026-04-23 - 2026-05-22 | I59: Ended | J59: Excellent | L59: 1.28 | M59: 2.551 | N59: Implementation | O59: M-08 Dismantle | P59: ISDP | Q59: 36 | R59: 5 | S59: 0.1389
A60: DC | B60: DC-Document_Controller-005 | C60: =Data_Master[[#This Row],[Uniq-ID]]&"-"&Data_Master[[#This Row],[Period]] -> DC-Document_Controller-005-M2 | D60: F Albert Jacob wx1504717 | E60: TELKOMSEL | G60: M2 | H60: 2026-04-23 - 2026-05-22 | I60: Ended | J60: Excellent | L60: 1.28 | M60: 2.551 | N60: Implementation | O60: Tagging Dismantle Material | P60: ISDP | Q60: 35 | R60: 5 | S60: 0.1429
A61: DC | B61: DC-Document_Controller-005 | C61: =Data_Master[[#This Row],[Uniq-ID]]&"-"&Data_Master[[#This Row],[Period]] -> DC-Document_Controller-005-M2 | D61: F Albert Jacob wx1504717 | E61: TELKOMSEL | G61: M2 | H61: 2026-04-23 - 2026-05-22 | I61: Ended | J61: Excellent | L61: 1.28 | M61: 2.551 | N61: Pre-implementation | O61: CAF Application | P61: ISDP | Q61: 26 | R61: 59 | S61: 2.2692
A62: DC | B62: DC-Document_Controller-005 | C62: =Data_Master[[#This Row],[Uniq-ID]]&"-"&Data_Master[[#This Row],[Period]] -> DC-Document_Controller-005-M3 | D62: F Albert Jacob wx1504717 | E62: TELKOMSEL | G62: M3 | H62: 2026-05-23 - 2026-06-22 | I62: Ended | J62: Normal | L62: 1 | M62: 1.23 | N62: Implementation | O62: Tagging Dismantle Material | P62: ISDP | Q62: 35 | R62: 2 | S62: 0.0571
...

Sheet Tagihan
X1: =SUBTOTAL(9,X3:X1149) -> 1938556000
A2: Site Code | B2: Name | C2: Project before | D2: Project Assign | E2: New Project | G2: Period Tagih | H2: Join Date | I2: Join Month | J2: Site Code.1 | K2: Site Name | L2: Regional | M2: Site ID | N2: Sub Contract NO. | O2: PR NO. | P2: PO NO. | Q2: PO Line NO. | R2: Shipment NO. | S2: Item Code | T2: Item Description | U2: Unit Price | V2: Requested Qty | W2: Payment Coef | X2: Total Price | Y2: Acceptance Date | Z2: Status | AA2: ISDP Status | AB2: Remarks | AC2: Action | AD2: Ibuy Status | AE2: ID Project | AF2: SO Number | AG2: Invoice Number | AH2: Invoice Date | AI2: Invoice Month
A3: PE-Project_Engineer-006 | B3: =_xlfn.XLOOKUP(J3,'Master Data 14-9-2026'!C:C,'Master Data 14-9-2026'!D:D) -> Viona Yose Ariani wx1504713 | D3: =_xlfn.XLOOKUP(J3,'Master Data 14-9-2026'!C:C,'Master Data 14-9-2026'!E:E) -> Enterprise | G3: M1 | H3: =_xlfn.XLOOKUP(J3,'Master Data 14-9-2026'!C:C,'Master Data 14-9-2026'!H:H) -> 2026-03-26 - 2026-04-25 | I3: =TEXT(DATEVALUE(LEFT(H3,10)),"mmmm") -> March | J3: PE-Project_Engineer-006-M1 | K3: PE-Project_Engineer-006-M1 | L3: Jabodetabek | M3: 200003104075020 | N3: FPA1091IDN26031710640667 | O3: 1.0912026e+17 | P3: 1091HG3728823-1 | Q3: 1 | R3: 1 | S3: 8828132635 | T3: Project Delivery Monitoring Services - Project Engineer | U3: 34220600 | V3: 1 | W3: =_xlfn.XLOOKUP(J3,'Master Data 14-9-2026'!C:C,'Master Data 14-9-2026'!L:L) -> 0 | X3: 34220600 | Y3: 2026-05-08 | Z3: Ended | AA3: Eror | AB3: PO associated item tidak ada | AE3: =_xlfn.XLOOKUP(L3,'[1]ID PROJECT'!E:E,'[1]ID PROJECT'!F:F) -> PRJ-KUT-KPU-TPED-2026-04-00071
A4: QC-Quality_Control-017 | B4: =_xlfn.XLOOKUP(J4,'Master Data 14-9-2026'!C:C,'Master Data 14-9-2026'!D:D) -> Arsetyo wx1507094 | D4: =_xlfn.XLOOKUP(J4,'Master Data 14-9-2026'!C:C,'Master Data 14-9-2026'!E:E) -> TELKOM | G4: M1 | H4: =_xlfn.XLOOKUP(J4,'Master Data 14-9-2026'!C:C,'Master Data 14-9-2026'!H:H) -> 2026-04-01 - 2026-04-30 | I4: =TEXT(DATEVALUE(LEFT(H4,10)),"mmmm") -> April | J4: QC-Quality_Control-017-M1 | K4: Enhancement NeutraDC | L4: Jabodetabek | M4: 200003102755020 | N4: FPA1091IDN26031710640667 | O4: 1.0912026e+17 | P4: 1091HG3728823-2 | Q4: 1 | R4: 1 | S4: 8828132636 | T4: QEHS Onsite Monitoring and Inspection - QC | U4: 36992000 | V4: 1 | W4: =_xlfn.XLOOKUP(J4,'Master Data 14-9-2026'!C:C,'Master Data 14-9-2026'!L:L) -> 1.1 | X4: 36992000 | Y4: 2026-05-08 | Z4: Ended | AA4: Approved | AD4: Invoice | AE4: =_xlfn.XLOOKUP(L4,'[1]ID PROJECT'!E:E,'[1]ID PROJECT'!F:F) -> PRJ-KUT-KPU-TPED-2026-04-00071 | AF4: SSO-KUT-KPU-NIUT-2026-07-03643 | AG4: 313/INV/KUT-PST/VII/2026 | AH4: 46230 | AI4: Juli
A5: QC-Quality_Control-018 | B5: =_xlfn.XLOOKUP(J5,'Master Data 14-9-2026'!C:C,'Master Data 14-9-2026'!D:D) -> Rifqi Adytia Fauzan wx1507719 | D5: =_xlfn.XLOOKUP(J5,'Master Data 14-9-2026'!C:C,'Master Data 14-9-2026'!E:E) -> TELKOM | G5: M1 | H5: =_xlfn.XLOOKUP(J5,'Master Data 14-9-2026'!C:C,'Master Data 14-9-2026'!H:H) -> 2026-04-01 - 2026-04-30 | I5: =TEXT(DATEVALUE(LEFT(H5,10)),"mmmm") -> April | J5: QC-Quality_Control-018-M1 | K5: Enhancement NeutraDC | L5: Jabodetabek | M5: 200003102756020 | N5: FPA1091IDN26031710640667 | O5: 1.0912026e+17 | P5: 1091HG3728823-2 | Q5: 2 | R5: 1 | S5: 8828132636 | T5: QEHS Onsite Monitoring and Inspection - QC | U5: 36992000 | V5: 1 | W5: =_xlfn.XLOOKUP(J5,'Master Data 14-9-2026'!C:C,'Master Data 14-9-2026'!L:L) -> 0.65 | X5: 36992000 | Y5: 2026-05-08 | Z5: Ended | AA5: Approved | AD5: Invoice | AE5: =_xlfn.XLOOKUP(L5,'[1]ID PROJECT'!E:E,'[1]ID PROJECT'!F:F) -> PRJ-KUT-KPU-TPED-2026-04-00071 | AF5: SSO-KUT-KPU-NIUT-2026-07-03643 | AG5: 313/INV/KUT-PST/VII/2026 | AH5: 46230 | AI5: Juli
A6: PE-Project_Engineer-018 | B6: =_xlfn.XLOOKUP(J6,'Master Data 14-9-2026'!C:C,'Master Data 14-9-2026'!D:D) -> Qudsiyah Zahra Ilham Naseela wx1507281 | D6: =_xlfn.XLOOKUP(J6,'Master Data 14-9-2026'!C:C,'Master Data 14-9-2026'!E:E) -> XLSMART | G6: M1 | H6: =_xlfn.XLOOKUP(J6,'Master Data 14-9-2026'!C:C,'Master Data 14-9-2026'!H:H) -> 2026-04-01 - 2026-04-30 | I6: =TEXT(DATEVALUE(LEFT(H6,10)),"mmmm") -> April | J6: PE-Project_Engineer-018-M1 | K6: Wisma Mulia | L6: Jabodetabek | M6: 200003104094020 | N6: FPA1091IDN26031710640667 | O6: 1.0912026e+17 | P6: 1091HG3728823-3 | Q6: 1 | R6: 1 | S6: 8828132635 | T6: Project Delivery Monitoring Services - Project Engineer | U6: 34220600 | V6: 1 | W6: =_xlfn.XLOOKUP(J6,'Master Data 14-9-2026'!C:C,'Master Data 14-9-2026'!L:L) -> 1.32 | X6: 34220600 | Y6: 2026-05-08 | Z6: Ended | AA6: Approved | AD6: Invoice | AE6: =_xlfn.XLOOKUP(L6,'[1]ID PROJECT'!E:E,'[1]ID PROJECT'!F:F) -> PRJ-KUT-KPU-TPED-2026-04-00071 | AF6: SSO-KUT-KPU-NIUT-2026-06-03073 | AG6: 261/INV/KUT-PST/VI/2026 | AH6: 46197 | AI6: Juni
A7: PE-Project_Engineer-021 | B7: =_xlfn.XLOOKUP(J7,'Master Data 14-9-2026'!C:C,'Master Data 14-9-2026'!D:D) -> Agus Hendra wx1506946 | D7: =_xlfn.XLOOKUP(J7,'Master Data 14-9-2026'!C:C,'Master Data 14-9-2026'!E:E) -> XLSMART | G7: M1 | H7: =_xlfn.XLOOKUP(J7,'Master Data 14-9-2026'!C:C,'Master Data 14-9-2026'!H:H) -> 2026-04-01 - 2026-04-30 | I7: =TEXT(DATEVALUE(LEFT(H7,10)),"mmmm") -> April | J7: PE-Project_Engineer-021-M1 | K7: Wisma Mulia | L7: Jabodetabek | M7: 200003104095020 | N7: FPA1091IDN26031710640667 | O7: 1.0912026e+17 | P7: 1091HG3728823-3 | Q7: 2 | R7: 1 | S7: 8828132635 | T7: Project Delivery Monitoring Services - Project Engineer | U7: 34220600 | V7: 1 | W7: =_xlfn.XLOOKUP(J7,'Master Data 14-9-2026'!C:C,'Master Data 14-9-2026'!L:L) -> 1 | X7: 34220600 | Y7: 2026-05-08 | Z7: =_xlfn.XLOOKUP(J7,'Master Data 14-9-2026'!C:C,'Master Data 14-9-2026'!I:I) -> Ended | AA7: Approved | AD7: Invoice | AE7: =_xlfn.XLOOKUP(L7,'[1]ID PROJECT'!E:E,'[1]ID PROJECT'!F:F) -> PRJ-KUT-KPU-TPED-2026-04-00071 | AF7: SSO-KUT-KPU-NIUT-2026-06-03073 | AG7: 261/INV/KUT-PST/VI/2026 | AH7: 46197 | AI7: Juni
A8: QC-Quality_Control-001 | B8: =_xlfn.XLOOKUP(J8,'Master Data 14-9-2026'!C:C,'Master Data 14-9-2026'!D:D) -> Leonard Ricardo Hutabarat wx1503633 | D8: =_xlfn.XLOOKUP(J8,'Master Data 14-9-2026'!C:C,'Master Data 14-9-2026'!E:E) -> XLSMART | G8: M1 | H8: =_xlfn.XLOOKUP(J8,'Master Data 14-9-2026'!C:C,'Master Data 14-9-2026'!H:H) -> 2026-03-23 - 2026-04-22 | I8: =TEXT(DATEVALUE(LEFT(H8,10)),"mmmm") -> March | J8: QC-Quality_Control-001-M1 | K8: Wisma Mulia | L8: Sumatera | M8: 200003104096020 | N8: FPA1091IDN26031710640667 | O8: 1.0912026e+17 | P8: 1091HG3728823-3 | Q8: 3 | R8: 1 | S8: 8828132636 | T8: QEHS Onsite Monitoring and Inspection - QC | U8: 36992000 | V8: 1 | W8: =_xlfn.XLOOKUP(J8,'Master Data 14-9-2026'!C:C,'Master Data 14-9-2026'!L:L) -> 1.5 | X8: 36992000 | Y8: 2026-05-08 | Z8: Ended | AA8: Approved | AD8: Invoice | AE8: =_xlfn.XLOOKUP(L8,'[1]ID PROJECT'!E:E,'[1]ID PROJECT'!F:F) -> PRJ-KUT-KPU-TPED-2026-04-00078 | AF8: SSO-KUT-KPU-NIUT-2026-06-03073 | AG8: 261/INV/KUT-PST/VI/2026 | AH8: 46197 | AI8: Juni
A9: QC-Quality_Control-002 | B9: =_xlfn.XLOOKUP(J9,'Master Data 14-9-2026'!C:C,'Master Data 14-9-2026'!D:D) -> Risman Nurjaman wx1503969 | D9: =_xlfn.XLOOKUP(J9,'Master Data 14-9-2026'!C:C,'Master Data 14-9-2026'!E:E) -> XLSMART | G9: M1 | H9: =_xlfn.XLOOKUP(J9,'Master Data 14-9-2026'!C:C,'Master Data 14-9-2026'!H:H) -> 2026-03-23 - 2026-04-22 | I9: =TEXT(DATEVALUE(LEFT(H9,10)),"mmmm") -> March | J9: QC-Quality_Control-002-M1 | K9: Wisma Mulia | L9: West Java | M9: 200003104097020 | N9: FPA1091IDN26031710640667 | O9: 1.0912026e+17 | P9: 1091HG3728823-3 | Q9: 4 | R9: 1 | S9: 8828132636 | T9: QEHS Onsite Monitoring and Inspection - QC | U9: 36992000 | V9: 1 | W9: =_xlfn.XLOOKUP(J9,'Master Data 14-9-2026'!C:C,'Master Data 14-9-2026'!L:L) -> 1.5 | X9: 36992000 | Y9: 2026-05-08 | Z9: Ended | AA9: Approved | AD9: Invoice | AE9: =_xlfn.XLOOKUP(L9,'[1]ID PROJECT'!E:E,'[1]ID PROJECT'!F:F) -> PRJ-KUT-KPU-TPED-2026-04-00074 | AF9: SSO-KUT-KPU-NIUT-2026-06-03073 | AG9: 261/INV/KUT-PST/VI/2026 | AH9: 46197 | AI9: Juni
A10: DC-Document_Controller-002 | B10: =_xlfn.XLOOKUP(J10,'Master Data 14-9-2026'!C:C,'Master Data 14-9-2026'!D:D) -> Rifan Azkia wx1504665 | D10: =_xlfn.XLOOKUP(J10,'Master Data 14-9-2026'!C:C,'Master Data 14-9-2026'!E:E) -> XLSMART | G10: M1 | H10: =_xlfn.XLOOKUP(J10,'Master Data 14-9-2026'!C:C,'Master Data 14-9-2026'!H:H) -> 2026-03-23 - 2026-04-22 | I10: =TEXT(DATEVALUE(LEFT(H10,10)),"mmmm") -> March | J10: DC-Document_Controller-002-M1 | K10: Wisma Mulia | L10: Sumbagsel | M10: 200003104079020 | N10: FPA1091IDN26031710640667 | O10: 1.0912026e+17 | P10: 1091HG3728823-3 | Q10: 5 | R10: 1 | S10: 8828132633 | T10: Project Delivery Monitoring Services - Document Control | U10: 28881900 | V10: 1 | W10: =_xlfn.XLOOKUP(J10,'Master Data 14-9-2026'!C:C,'Master Data 14-9-2026'!L:L) -> 0 | X10: 28881900 | Y10: 2026-05-08 | Z10: Ended | AA10: Approved | AD10: Invoice | AE10: =_xlfn.XLOOKUP(L10,'[1]ID PROJECT'!E:E,'[1]ID PROJECT'!F:F) -> PRJ-KUT-KPU-TPED-2026-04-00078 | AF10: SSO-KUT-KPU-NIUT-2026-06-03073 | AG10: 261/INV/KUT-PST/VI/2026 | AH10: 46197 | AI10: Juni
A11: DC-Document_Controller-006 | B11: =_xlfn.XLOOKUP(J11,'Master Data 14-9-2026'!C:C,'Master Data 14-9-2026'!D:D) -> Devi Dyah Palupi wx1503645 | D11: =_xlfn.XLOOKUP(J11,'Master Data 14-9-2026'!C:C,'Master Data 14-9-2026'!E:E) -> IOH | G11: M1 | H11: =_xlfn.XLOOKUP(J11,'Master Data 14-9-2026'!C:C,'Master Data 14-9-2026'!H:H) -> 2026-03-23 - 2026-04-22 | I11: =TEXT(DATEVALUE(LEFT(H11,10)),"mmmm") -> March | J11: DC-Document_Controller-006-M1 | K11: Wisma Mulia | L11: Bali Nusra | M11: 200003104080020 | N11: FPA1091IDN26031710640667 | O11: 1.0912026e+17 | P11: 1091HG3728823-3 | Q11: 6 | R11: 1 | S11: 8828132633 | T11: Project Delivery Monitoring Services - Document Control | U11: 28881900 | V11: 1 | W11: =_xlfn.XLOOKUP(J11,'Master Data 14-9-2026'!C:C,'Master Data 14-9-2026'!L:L) -> 0 | X11: 28881900 | Y11: 2026-05-08 | Z11: Ended | AA11: Approved | AD11: Invoice | AE11: =_xlfn.XLOOKUP(L11,'[1]ID PROJECT'!E:E,'[1]ID PROJECT'!F:F) -> PRJ-KUT-KPU-TPED-2026-04-00077 | AF11: SSO-KUT-KPU-NIUT-2026-06-03073 | AG11: 261/INV/KUT-PST/VI/2026 | AH11: 46197 | AI11: Juni
A12: DC-Document_Controller-007 | B12: =_xlfn.XLOOKUP(J12,'Master Data 14-9-2026'!C:C,'Master Data 14-9-2026'!D:D) -> Mauli Rizki Amelia wx1504666 | D12: =_xlfn.XLOOKUP(J12,'Master Data 14-9-2026'!C:C,'Master Data 14-9-2026'!E:E) -> XLSMART | G12: M1 | H12: =_xlfn.XLOOKUP(J12,'Master Data 14-9-2026'!C:C,'Master Data 14-9-2026'!H:H) -> 2026-03-26 - 2026-04-25 | I12: =TEXT(DATEVALUE(LEFT(H12,10)),"mmmm") -> March | J12: DC-Document_Controller-007-M1 | K12: Wisma Mulia | L12: Sumbagsel | M12: 200003104081020 | N12: FPA1091IDN26031710640667 | O12: 1.0912026e+17 | P12: 1091HG3728823-3 | Q12: 7 | R12: 1 | S12: 8828132633 | T12: Project Delivery Monitoring Services - Document Control | U12: 28881900 | V12: 1 | W12: =_xlfn.XLOOKUP(J12,'Master Data 14-9-2026'!C:C,'Master Data 14-9-2026'!L:L) -> 0.5 | X12: 28881900 | Y12: 2026-05-08 | Z12: Ended | AA12: Approved | AD12: Invoice | AE12: =_xlfn.XLOOKUP(L12,'[1]ID PROJECT'!E:E,'[1]ID PROJECT'!F:F) -> PRJ-KUT-KPU-TPED-2026-04-00078 | AF12: SSO-KUT-KPU-NIUT-2026-06-03073 | AG12: 261/INV/KUT-PST/VI/2026 | AH12: 46197 | AI12: Juni
A13: DC-Document_Controller-008 | B13: =_xlfn.XLOOKUP(J13,'Master Data 14-9-2026'!C:C,'Master Data 14-9-2026'!D:D) -> Nurmawaty wx1504714 | D13: =_xlfn.XLOOKUP(J13,'Master Data 14-9-2026'!C:C,'Master Data 14-9-2026'!E:E) -> XLSMART | G13: M1 | H13: =_xlfn.XLOOKUP(J13,'Master Data 14-9-2026'!C:C,'Master Data 14-9-2026'!H:H) -> 2026-03-28 - 2026-04-27 | I13: =TEXT(DATEVALUE(LEFT(H13,10)),"mmmm") -> March | J13: DC-Document_Controller-008-M1 | K13: Wisma Mulia | L13: Jabodetabek | M13: 200003104082020 | N13: FPA1091IDN26031710640667 | O13: 1.0912026e+17 | P13: 1091HG3728823-3 | Q13: 8 | R13: 1 | S13: 8828132633 | T13: Project Delivery Monitoring Services - Document Control | U13: 28881900 | V13: 1 | W13: =_xlfn.XLOOKUP(J13,'Master Data 14-9-2026'!C:C,'Master Data 14-9-2026'!L:L) -> 1.5 | X13: 28881900 | Y13: 2026-05-08 | Z13: Ended | AA13: Approved | AD13: Invoice | AE13: =_xlfn.XLOOKUP(L13,'[1]ID PROJECT'!E:E,'[1]ID PROJECT'!F:F) -> PRJ-KUT-KPU-TPED-2026-04-00071 | AF13: SSO-KUT-KPU-NIUT-2026-06-03073 | AG13: 261/INV/KUT-PST/VI/2026 | AH13: 46197 | AI13: Juni
A14: DC-Document_Controller-014 | B14: =_xlfn.XLOOKUP(J14,'Master Data 14-9-2026'!C:C,'Master Data 14-9-2026'!D:D) -> Didit Irawan wx1504645 | D14: =_xlfn.XLOOKUP(J14,'Master Data 14-9-2026'!C:C,'Master Data 14-9-2026'!E:E) -> XLSMART | G14: M1 | H14: =_xlfn.XLOOKUP(J14,'Master Data 14-9-2026'!C:C,'Master Data 14-9-2026'!H:H) -> 2026-03-30 - 2026-04-29 | I14: =TEXT(DATEVALUE(LEFT(H14,10)),"mmmm") -> March | J14: DC-Document_Controller-014-M1 | K14: Wisma Mulia | L14: Jabodetabek | M14: 200003104083020 | N14: FPA1091IDN26031710640667 | O14: 1.0912026e+17 | P14: 1091HG3728823-3 | Q14: 9 | R14: 1 | S14: 8828132633 | T14: Project Delivery Monitoring Services - Document Control | U14: 28881900 | V14: 1 | W14: =_xlfn.XLOOKUP(J14,'Master Data 14-9-2026'!C:C,'Master Data 14-9-2026'!L:L) -> 0.5 | X14: 28881900 | Y14: 2026-05-08 | Z14: Ended | AA14: Approved | AD14: Invoice | AE14: =_xlfn.XLOOKUP(L14,'[1]ID PROJECT'!E:E,'[1]ID PROJECT'!F:F) -> PRJ-KUT-KPU-TPED-2026-04-00071 | AF14: SSO-KUT-KPU-NIUT-2026-06-03073 | AG14: 261/INV/KUT-PST/VI/2026 | AH14: 46197 | AI14: Juni
A15: PE-Project_Engineer-001 | B15: =_xlfn.XLOOKUP(J15,'Master Data 14-9-2026'!C:C,'Master Data 14-9-2026'!D:D) -> Rizqy Ramadhan Pramono wx1503632 | D15: =_xlfn.XLOOKUP(J15,'Master Data 14-9-2026'!C:C,'Master Data 14-9-2026'!E:E) -> XLSMART | G15: M1 | H15: =_xlfn.XLOOKUP(J15,'Master Data 14-9-2026'!C:C,'Master Data 14-9-2026'!H:H) -> 2026-03-23 - 2026-04-22 | I15: =TEXT(DATEVALUE(LEFT(H15,10)),"mmmm") -> March | J15: PE-Project_Engineer-001-M1 | K15: Wisma Mulia | L15: Sumatera | M15: 200003104088020 | N15: FPA1091IDN26031710640667 | O15: 1.0912026e+17 | P15: 1091HG3728823-3 | Q15: 10 | R15: 1 | S15: 8828132635 | T15: Project Delivery Monitoring Services - Project Engineer | U15: 34220600 | V15: 1 | W15: =_xlfn.XLOOKUP(J15,'Master Data 14-9-2026'!C:C,'Master Data 14-9-2026'!L:L) -> 1 | X15: 34220600 | Y15: 2026-05-08 | Z15: =_xlfn.XLOOKUP(J15,'Master Data 14-9-2026'!C:C,'Master Data 14-9-2026'!I:I) -> Ended | AA15: Approved | AD15: Invoice | AE15: =_xlfn.XLOOKUP(L15,'[1]ID PROJECT'!E:E,'[1]ID PROJECT'!F:F) -> PRJ-KUT-KPU-TPED-2026-04-00078 | AF15: SSO-KUT-KPU-NIUT-2026-06-03073 | AG15: 261/INV/KUT-PST/VI/2026 | AH15: 46197 | AI15: Juni
A16: DC-Document_Controller-023 | B16: =_xlfn.XLOOKUP(J16,'Master Data 14-9-2026'!C:C,'Master Data 14-9-2026'!D:D) -> Ika Setianingsih wx1507364 | D16: =_xlfn.XLOOKUP(J16,'Master Data 14-9-2026'!C:C,'Master Data 14-9-2026'!E:E) -> XLSMART | G16: M1 | H16: =_xlfn.XLOOKUP(J16,'Master Data 14-9-2026'!C:C,'Master Data 14-9-2026'!H:H) -> 2026-04-01 - 2026-04-30 | I16: =TEXT(DATEVALUE(LEFT(H16,10)),"mmmm") -> April | J16: DC-Document_Controller-023-M1 | K16: Wisma Mulia | L16: Jabodetabek | M16: 200003104084020 | N16: FPA1091IDN26031710640667 | O16: 1.0912026e+17 | P16: 1091HG3728823-3 | Q16: 11 | R16: 1 | S16: 8828132633 | T16: Project Delivery Monitoring Services - Document Control | U16: 28881900 | V16: 1 | W16: =_xlfn.XLOOKUP(J16,'Master Data 14-9-2026'!C:C,'Master Data 14-9-2026'!L:L) -> 1.5 | X16: 28881900 | Y16: 2026-05-08 | Z16: Ended | AA16: Approved | AD16: Invoice | AE16: =_xlfn.XLOOKUP(L16,'[1]ID PROJECT'!E:E,'[1]ID PROJECT'!F:F) -> PRJ-KUT-KPU-TPED-2026-04-00071 | AF16: SSO-KUT-KPU-NIUT-2026-06-03073 | AG16: 261/INV/KUT-PST/VI/2026 | AH16: 46197 | AI16: Juni
A17: DC-Document_Controller-025 | B17: =_xlfn.XLOOKUP(J17,'Master Data 14-9-2026'!C:C,'Master Data 14-9-2026'!D:D) -> Aliyah wx1507137 | D17: =_xlfn.XLOOKUP(J17,'Master Data 14-9-2026'!C:C,'Master Data 14-9-2026'!E:E) -> XLSMART | G17: M1 | H17: =_xlfn.XLOOKUP(J17,'Master Data 14-9-2026'!C:C,'Master Data 14-9-2026'!H:H) -> 2026-04-01 - 2026-04-30 | I17: =TEXT(DATEVALUE(LEFT(H17,10)),"mmmm") -> April | J17: DC-Document_Controller-025-M1 | K17: Wisma Mulia | L17: Kalimantan | M17: 200003104085020 | N17: FPA1091IDN26031710640667 | O17: 1.0912026e+17 | P17: 1091HG3728823-3 | Q17: 12 | R17: 1 | S17: 8828132633 | T17: Project Delivery Monitoring Services - Document Control | U17: 28881900 | V17: 1 | W17: =_xlfn.XLOOKUP(J17,'Master Data 14-9-2026'!C:C,'Master Data 14-9-2026'!L:L) -> 1.05 | X17: 28881900 | Y17: 2026-05-08 | Z17: Ended | AA17: Approved | AD17: Invoice | AE17: =_xlfn.XLOOKUP(L17,'[1]ID PROJECT'!E:E,'[1]ID PROJECT'!F:F) -> PRJ-KUT-KPU-TPED-2026-04-00079 | AF17: SSO-KUT-KPU-NIUT-2026-06-03073 | AG17: 261/INV/KUT-PST/VI/2026 | AH17: 46197 | AI17: Juni
A18: PE-Project_Engineer-004 | B18: =_xlfn.XLOOKUP(J18,'Master Data 14-9-2026'!C:C,'Master Data 14-9-2026'!D:D) -> Rayza Mayga Pratama wx1504644 | D18: =_xlfn.XLOOKUP(J18,'Master Data 14-9-2026'!C:C,'Master Data 14-9-2026'!E:E) -> XLSMART | G18: M1 | H18: =_xlfn.XLOOKUP(J18,'Master Data 14-9-2026'!C:C,'Master Data 14-9-2026'!H:H) -> 2026-03-23 - 2026-04-22 | I18: =TEXT(DATEVALUE(LEFT(H18,10)),"mmmm") -> March | J18: PE-Project_Engineer-004-M1 | K18: Wisma Mulia | L18: Jabodetabek | M18: 200003104089020 | N18: FPA1091IDN26031710640667 | O18: 1.0912026e+17 | P18: 1091HG3728823-3 | Q18: 13 | R18: 1 | S18: 8828132635 | T18: Project Delivery Monitoring Services - Project Engineer | U18: 34220600 | V18: 1 | W18: =_xlfn.XLOOKUP(J18,'Master Data 14-9-2026'!C:C,'Master Data 14-9-2026'!L:L) -> 1.01 | X18: 34220600 | Y18: 2026-05-08 | Z18: Ended | AA18: Approved | AD18: Invoice | AE18: =_xlfn.XLOOKUP(L18,'[1]ID PROJECT'!E:E,'[1]ID PROJECT'!F:F) -> PRJ-KUT-KPU-TPED-2026-04-00071 | AF18: SSO-KUT-KPU-NIUT-2026-06-03073 | AG18: 261/INV/KUT-PST/VI/2026 | AH18: 46197 | AI18: Juni
A19: DC-Document_Controller-026 | B19: =_xlfn.XLOOKUP(J19,'Master Data 14-9-2026'!C:C,'Master Data 14-9-2026'!D:D) -> Salsabila Ulya Nabilah Fuad wx1507138 | D19: =_xlfn.XLOOKUP(J19,'Master Data 14-9-2026'!C:C,'Master Data 14-9-2026'!E:E) -> XLSMART | G19: M1 | H19: =_xlfn.XLOOKUP(J19,'Master Data 14-9-2026'!C:C,'Master Data 14-9-2026'!H:H) -> 2026-04-01 - 2026-04-30 | I19: =TEXT(DATEVALUE(LEFT(H19,10)),"mmmm") -> April | J19: DC-Document_Controller-026-M1 | K19: Wisma Mulia | L19: Kalimantan | M19: 200003104086020 | N19: FPA1091IDN26031710640667 | O19: 1.0912026e+17 | P19: 1091HG3728823-3 | Q19: 14 | R19: 1 | S19: 8828132633 | T19: Project Delivery Monitoring Services - Document Control | U19: 28881900 | V19: 1 | W19: =_xlfn.XLOOKUP(J19,'Master Data 14-9-2026'!C:C,'Master Data 14-9-2026'!L:L) -> 0.5 | X19: 28881900 | Y19: 2026-05-08 | Z19: Ended | AA19: Approved | AD19: Invoice | AE19: =_xlfn.XLOOKUP(L19,'[1]ID PROJECT'!E:E,'[1]ID PROJECT'!F:F) -> PRJ-KUT-KPU-TPED-2026-04-00079 | AF19: SSO-KUT-KPU-NIUT-2026-06-03073 | AG19: 261/INV/KUT-PST/VI/2026 | AH19: 46197 | AI19: Juni
A20: DC-Document_Controller-028 | B20: =_xlfn.XLOOKUP(J20,'Master Data 14-9-2026'!C:C,'Master Data 14-9-2026'!D:D) -> Cahyo Suryo Bhuwono Winarso wx1507283 | D20: =_xlfn.XLOOKUP(J20,'Master Data 14-9-2026'!C:C,'Master Data 14-9-2026'!E:E) -> XLSMART | G20: M1 | H20: =_xlfn.XLOOKUP(J20,'Master Data 14-9-2026'!C:C,'Master Data 14-9-2026'!H:H) -> 2026-04-01 - 2026-04-30 | I20: =TEXT(DATEVALUE(LEFT(H20,10)),"mmmm") -> April | J20: DC-Document_Controller-028-M1 | K20: Wisma Mulia | L20: West Java | M20: 200003104087020 | N20: FPA1091IDN26031710640667 | O20: 1.0912026e+17 | P20: 1091HG3728823-3 | Q20: 15 | R20: 1 | S20: 8828132633 | T20: Project Delivery Monitoring Services - Document Control | U20: 28881900 | V20: 1 | W20: =_xlfn.XLOOKUP(J20,'Master Data 14-9-2026'!C:C,'Master Data 14-9-2026'!L:L) -> 0 | X20: 28881900 | Y20: 2026-05-08 | Z20: Ended | AA20: Approved | AD20: Invoice | AE20: =_xlfn.XLOOKUP(L20,'[1]ID PROJECT'!E:E,'[1]ID PROJECT'!F:F) -> PRJ-KUT-KPU-TPED-2026-04-00074 | AF20: SSO-KUT-KPU-NIUT-2026-06-03073 | AG20: 261/INV/KUT-PST/VI/2026 | AH20: 46197 | AI20: Juni
A21: PE-Project_Engineer-009 | B21: =_xlfn.XLOOKUP(J21,'Master Data 14-9-2026'!C:C,'Master Data 14-9-2026'!D:D) -> Sugeng Andrianto wx1504668 | D21: =_xlfn.XLOOKUP(J21,'Master Data 14-9-2026'!C:C,'Master Data 14-9-2026'!E:E) -> XLSMART | G21: M1 | H21: =_xlfn.XLOOKUP(J21,'Master Data 14-9-2026'!C:C,'Master Data 14-9-2026'!H:H) -> 2026-03-30 - 2026-04-29 | I21: =TEXT(DATEVALUE(LEFT(H21,10)),"mmmm") -> March | J21: PE-Project_Engineer-009-M1 | K21: Wisma Mulia | L21: Sumatera | M21: 200003104090020 | N21: FPA1091IDN26031710640667 | O21: 1.0912026e+17 | P21: 1091HG3728823-3 | Q21: 16 | R21: 1 | S21: 8828132635 | T21: Project Delivery Monitoring Services - Project Engineer | U21: 34220600 | V21: 1 | W21: =_xlfn.XLOOKUP(J21,'Master Data 14-9-2026'!C:C,'Master Data 14-9-2026'!L:L) -> 1.05 | X21: 34220600 | Y21: 2026-05-08 | Z21: Ended | AA21: Approved | AD21: Invoice | AE21: =_xlfn.XLOOKUP(L21,'[1]ID PROJECT'!E:E,'[1]ID PROJECT'!F:F) -> PRJ-KUT-KPU-TPED-2026-04-00078 | AF21: SSO-KUT-KPU-NIUT-2026-06-03073 | AG21: 261/INV/KUT-PST/VI/2026 | AH21: 46197 | AI21: Juni
A22: DC-Document_Controller-033 | B22: =_xlfn.XLOOKUP(J22,'Master Data 14-9-2026'!C:C,'Master Data 14-9-2026'!D:D) -> Gema Marhayen wx1506940 | D22: =_xlfn.XLOOKUP(J22,'Master Data 14-9-2026'!C:C,'Master Data 14-9-2026'!E:E) -> XLSMART | E22: XL DC033 | G22: M1 | H22: =_xlfn.XLOOKUP(J22,'Master Data 14-9-2026'!C:C,'Master Data 14-9-2026'!H:H) -> 2026-04-01 - 2026-04-30 | I22: =TEXT(DATEVALUE(LEFT(H22,10)),"mmmm") -> April | J22: DC-Document_Controller-033-M1 | K22: Wisma Mulia | L22: Jabodetabek | M22: 200003104077020 | N22: FPA1091IDN26031710640667 | O22: 1.0912026e+17 | P22: 1091HG3728823-3 | Q22: 17 | R22: 1 | S22: 8828132633 | T22: Project Delivery Monitoring Services - Document Control | U22: 28881900 | V22: 1 | W22: =_xlfn.XLOOKUP(J22,'Master Data 14-9-2026'!C:C,'Master Data 14-9-2026'!L:L) -> 1.06 | X22: 28881900 | Y22: 2026-05-08 | Z22: Ended | AA22: Approved | AC22: Confirm dean | AD22: Invoice | AE22: =_xlfn.XLOOKUP(L22,'[1]ID PROJECT'!E:E,'[1]ID PROJECT'!F:F) -> PRJ-KUT-KPU-TPED-2026-04-00071 | AF22: SSO-KUT-KPU-NIUT-2026-09-04608 | AG22: 392/INV/KUT-PST/IX/2026 | AH22: 46267 | AI22: September
A23: QC-Quality_Control-004 | B23: =_xlfn.XLOOKUP(J23,'Master Data 14-9-2026'!C:C,'Master Data 14-9-2026'!D:D) -> Dewi Nur Annisa wx1503631 | D23: =_xlfn.XLOOKUP(J23,'Master Data 14-9-2026'!C:C,'Master Data 14-9-2026'!E:E) -> XLSMART | G23: M1 | H23: =_xlfn.XLOOKUP(J23,'Master Data 14-9-2026'!C:C,'Master Data 14-9-2026'!H:H) -> 2026-03-25 - 2026-04-24 | I23: =TEXT(DATEVALUE(LEFT(H23,10)),"mmmm") -> March | J23: QC-Quality_Control-004-M1 | K23: Wisma Mulia | L23: Sumatera | M23: 200003104098020 | N23: FPA1091IDN26031710640667 | O23: 1.0912026e+17 | P23: 1091HG3728823-3 | Q23: 18 | R23: 1 | S23: 8828132636 | T23: QEHS Onsite Monitoring and Inspection - QC | U23: 36992000 | V23: 1 | W23: =_xlfn.XLOOKUP(J23,'Master Data 14-9-2026'!C:C,'Master Data 14-9-2026'!L:L) -> 1.3 | X23: 36992000 | Y23: 2026-05-08 | Z23: Ended | AA23: Approved | AD23: Invoice | AE23: =_xlfn.XLOOKUP(L23,'[1]ID PROJECT'!E:E,'[1]ID PROJECT'!F:F) -> PRJ-KUT-KPU-TPED-2026-04-00078 | AF23: SSO-KUT-KPU-NIUT-2026-06-03073 | AG23: 261/INV/KUT-PST/VI/2026 | AH23: 46197 | AI23: Juni
A24: PE-Project_Engineer-010 | B24: =_xlfn.XLOOKUP(J24,'Master Data 14-9-2026'!C:C,'Master Data 14-9-2026'!D:D) -> Fauzan Fathoni wx1504667 | D24: =_xlfn.XLOOKUP(J24,'Master Data 14-9-2026'!C:C,'Master Data 14-9-2026'!E:E) -> XLSMART | G24: M1 | H24: =_xlfn.XLOOKUP(J24,'Master Data 14-9-2026'!C:C,'Master Data 14-9-2026'!H:H) -> 2026-03-30 - 2026-04-29 | I24: =TEXT(DATEVALUE(LEFT(H24,10)),"mmmm") -> March | J24: PE-Project_Engineer-010-M1 | K24: Wisma Mulia | L24: Sumatera | M24: 200003104091020 | N24: FPA1091IDN26031710640667 | O24: 1.0912026e+17 | P24: 1091HG3728823-3 | Q24: 19 | R24: 1 | S24: 8828132635 | T24: Project Delivery Monitoring Services - Project Engineer | U24: 34220600 | V24: 1 | W24: =_xlfn.XLOOKUP(J24,'Master Data 14-9-2026'!C:C,'Master Data 14-9-2026'!L:L) -> 1.5 | X24: 34220600 | Y24: 2026-05-08 | Z24: Ended | AA24: Approved | AD24: Invoice | AE24: =_xlfn.XLOOKUP(L24,'[1]ID PROJECT'!E:E,'[1]ID PROJECT'!F:F) -> PRJ-KUT-KPU-TPED-2026-04-00078 | AF24: SSO-KUT-KPU-NIUT-2026-06-03073 | AG24: 261/INV/KUT-PST/VI/2026 | AH24: 46197 | AI24: Juni
A25: QC-Quality_Control-005 | B25: =_xlfn.XLOOKUP(J25,'Master Data 14-9-2026'!C:C,'Master Data 14-9-2026'!D:D) -> Febby Ramadhan Ahmad Suhandi wx1503968 | D25: =_xlfn.XLOOKUP(J25,'Master Data 14-9-2026'!C:C,'Master Data 14-9-2026'!E:E) -> XLSMART | G25: M1 | H25: =_xlfn.XLOOKUP(J25,'Master Data 14-9-2026'!C:C,'Master Data 14-9-2026'!H:H) -> 2026-03-25 - 2026-04-24 | I25: =TEXT(DATEVALUE(LEFT(H25,10)),"mmmm") -> March | J25: QC-Quality_Control-005-M1 | K25: Wisma Mulia | L25: Jabodetabek | M25: 200003104099020 | N25: FPA1091IDN26031710640667 | O25: 1.0912026e+17 | P25: 1091HG3728823-3 | Q25: 20 | R25: 1 | S25: 8828132636 | T25: QEHS Onsite Monitoring and Inspection - QC | U25: 36992000 | V25: 1 | W25: =_xlfn.XLOOKUP(J25,'Master Data 14-9-2026'!C:C,'Master Data 14-9-2026'!L:L) -> 1.5 | X25: 36992000 | Y25: 2026-05-08 | Z25: Ended | AA25: Approved | AD25: Invoice | AE25: =_xlfn.XLOOKUP(L25,'[1]ID PROJECT'!E:E,'[1]ID PROJECT'!F:F) -> PRJ-KUT-KPU-TPED-2026-04-00071 | AF25: SSO-KUT-KPU-NIUT-2026-06-03073 | AG25: 261/INV/KUT-PST/VI/2026 | AH25: 46197 | AI25: Juni | AJ25: reklas revenue
A26: PE-Project_Engineer-015 | B26: =_xlfn.XLOOKUP(J26,'Master Data 14-9-2026'!C:C,'Master Data 14-9-2026'!D:D) -> Yonathan Janmorga wx1507284 | D26: =_xlfn.XLOOKUP(J26,'Master Data 14-9-2026'!C:C,'Master Data 14-9-2026'!E:E) -> XLSMART | G26: M1 | H26: =_xlfn.XLOOKUP(J26,'Master Data 14-9-2026'!C:C,'Master Data 14-9-2026'!H:H) -> 2026-04-01 - 2026-04-30 | I26: =TEXT(DATEVALUE(LEFT(H26,10)),"mmmm") -> April | J26: PE-Project_Engineer-015-M1 | K26: Wisma Mulia | L26: West Java | M26: 200003104092020 | N26: FPA1091IDN26031710640667 | O26: 1.0912026e+17 | P26: 1091HG3728823-3 | Q26: 21 | R26: 1 | S26: 8828132635 | T26: Project Delivery Monitoring Services - Project Engineer | U26: 34220600 | V26: 1 | W26: =_xlfn.XLOOKUP(J26,'Master Data 14-9-2026'!C:C,'Master Data 14-9-2026'!L:L) -> 1.5 | X26: 34220600 | Y26: 2026-05-08 | Z26: Ended | AA26: Approved | AD26: Invoice | AE26: =_xlfn.XLOOKUP(L26,'[1]ID PROJECT'!E:E,'[1]ID PROJECT'!F:F) -> PRJ-KUT-KPU-TPED-2026-04-00074 | AF26: SSO-KUT-KPU-NIUT-2026-06-03073 | AG26: 261/INV/KUT-PST/VI/2026 | AH26: 46197 | AI26: Juni
A27: QC-Quality_Control-006 | B27: =_xlfn.XLOOKUP(J27,'Master Data 14-9-2026'!C:C,'Master Data 14-9-2026'!D:D) -> Heri Kusnanto wx1503971 | D27: =_xlfn.XLOOKUP(J27,'Master Data 14-9-2026'!C:C,'Master Data 14-9-2026'!E:E) -> XLSMART | G27: M1 | H27: =_xlfn.XLOOKUP(J27,'Master Data 14-9-2026'!C:C,'Master Data 14-9-2026'!H:H) -> 2026-03-26 - 2026-04-25 | I27: =TEXT(DATEVALUE(LEFT(H27,10)),"mmmm") -> March | J27: QC-Quality_Control-006-M1 | K27: Wisma Mulia | L27: Jabodetabek | M27: 200003104100020 | N27: FPA1091IDN26031710640667 | O27: 1.0912026e+17 | P27: 1091HG3728823-3 | Q27: 22 | R27: 1 | S27: 8828132636 | T27: QEHS Onsite Monitoring and Inspection - QC | U27: 36992000 | V27: 1 | W27: =_xlfn.XLOOKUP(J27,'Master Data 14-9-2026'!C:C,'Master Data 14-9-2026'!L:L) -> 1.5 | X27: 36992000 | Y27: 2026-05-08 | Z27: Ended | AA27: Approved | AD27: Invoice | AE27: =_xlfn.XLOOKUP(L27,'[1]ID PROJECT'!E:E,'[1]ID PROJECT'!F:F) -> PRJ-KUT-KPU-TPED-2026-04-00071 | AF27: SSO-KUT-KPU-NIUT-2026-06-03073 | AG27: 261/INV/KUT-PST/VI/2026 | AH27: 46197 | AI27: Juni
